<?xml version="1.0" encoding="UTF-8"?>
<robot xmlns:xacro="http://wiki.ros.org/xacro">

  <xacro:include filename="$(find mbot_description)/urdf/common.xacro" />

  <xacro:macro name="mbot_ranger_dashing_raptor" params="prefix parent *origin">
    <!-- LINKS -->
    <!-- base link -->
    <link name="${prefix}base_link">
      <!-- Default inertial for Gazebo/Ingnition - copy and edit block from 'common.xacro'
           to get more realistic behaviour-->
      <xacro:default_inertial/>
      <visual>
        <origin xyz="0 0 0" rpy="0 0 0" />
        <geometry>
          <box size="0.025 0.125 0.025" />
<!--           <mesh filename="package://mbot_description/meshes/mbot_ranger_dashing_raptor/visual/base_link.dae" /> -->
        </geometry>
      </visual>
      <collision>
        <origin xyz="0 0 0" rpy="0 0 0" />
        <geometry>
          <box size="0.025 0.125 0.025" />
<!--           <mesh filename="package://mbot_description/meshes/mbot_ranger_dashing_raptor/collision/base_link.stl" /> -->
        </geometry>
      </collision>
    </link>

    <link name="${prefix}chassis">
      <!-- Default inertial for Gazebo/Ingnition - copy and edit block from 'common.xacro'
           to get more realistic behaviour-->
      <xacro:default_inertial/>
      <visual>
        <origin xyz="0.07 0 0" rpy="0 0 0" />
        <geometry>
          <box size="0.14 0.125 0.025" />
<!--           <mesh filename="package://mbot_description/meshes/mbot_ranger_dashing_raptor/visual/base_link.dae" /> -->
        </geometry>
      </visual>
      <collision>
        <origin xyz="0.07 0 0" rpy="0 0 0" />
        <geometry>
          <box size="0.14 0.125 0.025" />
<!--           <mesh filename="package://mbot_description/meshes/mbot_ranger_dashing_raptor/collision/base_link.stl" /> -->
        </geometry>
      </collision>
    </link>

    <!-- left  wheel -->
    <link name="${prefix}caster_wheel">
      <!-- Default inertial for Gazebo/Ingnition - copy and edit block from 'common.xacro'
           to get more realistic behaviour-->
      <xacro:default_inertial/>
      <visual>
        <origin xyz="0 0 0" rpy="0 0 0" />
        <geometry>
          <sphere radius="0.01" />
<!--           <mesh filename="package://mbot_description/meshes/mbot_ranger_dashing_raptor/visual/left_wheel.dae" /> -->
        </geometry>
      </visual>
      <collision>
        <origin xyz="0 0 0" rpy="0 0 0" />
        <geometry>
          <sphere radius="0.01" />
<!--           <mesh filename="package://mbot_description/meshes/mbot_ranger_dashing_raptor/collision/left_wheel.stl" /> -->
        </geometry>
      </collision>
    </link>

    <!-- left  wheel -->
    <link name="${prefix}left_wheel">
      <!-- Default inertial for Gazebo/Ingnition - copy and edit block from 'common.xacro'
           to get more realistic behaviour-->
      <xacro:default_inertial/>
      <visual>
        <origin xyz="0 0.008 0" rpy="0 ${pi/2} ${pi/2}" />
        <geometry>
          <cylinder length="0.016" radius="0.0325" />
<!--           <mesh filename="package://mbot_description/meshes/mbot_ranger_dashing_raptor/visual/left_wheel.dae" /> -->
        </geometry>
      </visual>
      <collision>
        <origin xyz="0 0.008 0" rpy="0 ${pi/2} ${pi/2}" />
        <geometry>
          <cylinder length="0.016" radius="0.0325" />
<!--           <mesh filename="package://mbot_description/meshes/mbot_ranger_dashing_raptor/collision/left_wheel.stl" /> -->
        </geometry>
      </collision>
    </link>
    <!-- right wheel -->
    <link name="${prefix}right_wheel">
      <!-- Default inertial for Gazebo/Ingnition - copy and edit block from 'common.xacro'
           to get more realistic behaviour-->
      <xacro:default_inertial/>
      <visual>
        <origin xyz="0 -0.008 0" rpy="0 ${pi/2} ${pi/2}" />
        <geometry>
          <cylinder length="0.016" radius="0.0325" />
<!--           <mesh filename="package://mbot_description/meshes/mbot_ranger_dashing_raptor/visual/right_wheel.dae" /> -->
        </geometry>
      </visual>
      <collision>
        <origin xyz="0 -0.008 0" rpy="0 ${pi/2} ${pi/2}" />
        <geometry>
          <cylinder length="0.016" radius="0.0325" />
<!--           <mesh filename="package://mbot_description/meshes/mbot_ranger_dashing_raptor/collision/right_wheel.stl"  /> -->
        </geometry>
      </collision>
    </link>
    <!-- END LINKS -->

    <!-- JOINTS -->
    <joint name="${prefix}fixture1" type="fixed">
      <origin xyz="0.025 0 0.04" rpy="0 0 0" />
      <parent link="${prefix}base_link" />
      <child link="${prefix}chassis" />
      <axis xyz="0 0 1" />
    </joint>

    <joint name="${prefix}fixture2" type="fixed">
      <origin xyz="0.14 0 -0.0625" rpy="0 0 0" /> <!-- should touch ground while chassis is level -->
      <parent link="${prefix}chassis" />
      <child link="${prefix}caster_wheel" />
      <axis xyz="0 0 1" />
    </joint>

    <!-- joint 1 -->
    <joint name="${prefix}joint1" type="revolute">
      <origin xyz="0 -0.0625 0" rpy="0 0 0" />
      <parent link="${prefix}base_link" />
      <child link="${prefix}right_wheel" />
      <axis xyz="0 1 0" />
      <limit effort="0" lower="${radians(-180)}" upper="${radians(180)}" velocity="${radians(180)}" />
    </joint>
    <!-- joint 2 -->
    <joint name="${prefix}joint2" type="revolute">
      <origin xyz="0 0.0625 0" rpy="0 0 0" />
      <parent link="${prefix}base_link" />
      <child link="${prefix}left_wheel" />
      <axis xyz="0 1 0" />
      <limit effort="0" lower="${radians(-180)}" upper="${radians(180)}" velocity="${radians(180)}" />
    </joint>
    <!-- END JOINTS -->


  </xacro:macro>
</robot>
